<sdf version='1.7'>
  <model name='open_manipulator_x'>
    <joint name='world_fixed' type='fixed'>
      <pose relative_to='__model__'>0 0 0 0 -0 0</pose>
      <parent>world</parent>
      <child>link0</child>
    </joint>
    <link name='link0'>
      <pose relative_to='world_fixed'>0 0 0 0 -0 0</pose>
      <inertial>
        <pose>0 0 0 0 -0 0</pose>
        <mass>100</mass>
        <inertia>
          <ixx>1</ixx>
          <ixy>0</ixy>
          <ixz>0</ixz>
          <iyy>1</iyy>
          <iyz>0</iyz>
          <izz>1</izz>
        </inertia>
      </inertial>
      <collision name='link0_collision'>
        <pose>0 0 0 0 -0 0</pose>
        <geometry>
          <box>
            <size>0.8 0.05 0.03</size>
          </box>
        </geometry>
      </collision>
      <visual name='link0_visual'>
        <pose>0 0 0 0 -0 0</pose>
        <geometry>
          <box>
            <size>0.8 0.05 0.03</size>
          </box>
        </geometry>
      </visual>
    </link>
    <joint name='prismatic_joint' type='prismatic'>
      <pose relative_to='link0'>0 0 0 0 0 -1.5707</pose>
      <parent>link0</parent>
      <child>link1</child>
      <axis>
        <xyz>1 0 0</xyz>
        <limit>
          <lower>-35</lower>
          <upper>35</upper>
          <effort>1000</effort>
          <velocity>20</velocity>
        </limit>
        <dynamics>
          <damping>10</damping>
          <friction>1</friction>
          <spring_reference>0</spring_reference>
          <spring_stiffness>0</spring_stiffness>
        </dynamics>
      </axis>
    </joint>
    <link name='link1'>
      <pose relative_to='prismatic_joint'>0 0 0 0 -0 0</pose>
      <inertial>
        <pose>0.000309 0 -0.000122 0 -0 0</pose>
        <mass>0.07912</mass>
        <inertia>
          <ixx>1.25052e-05</ixx>
          <ixy>0</ixy>
          <ixz>-1.78552e-07</ixz>
          <iyy>2.18984e-05</iyy>
          <iyz>0</iyz>
          <izz>1.92674e-05</izz>
        </inertia>
      </inertial>
      <collision name='link1_collision'>
        <pose>0 0 0 0 -0 0</pose>
        <geometry>
          <mesh>
            <scale>0.001 0.001 0.001</scale>
            <uri>file:///home/csi/TTR_ws/install/open_manipulator_x_description/share/open_manipulator_x_description/meshes/chain_link1.stl</uri>
          </mesh>
        </geometry>
        <surface>
          <contact>
            <ode/>
          </contact>
          <friction>
            <ode/>
          </friction>
        </surface>
      </collision>
      <visual name='link1_visual'>
        <pose>0 0 0 0 -0 0</pose>
        <geometry>
          <mesh>
            <scale>0.001 0.001 0.001</scale>
            <uri>file:///home/csi/TTR_ws/install/open_manipulator_x_description/share/open_manipulator_x_description/meshes/chain_link1.stl</uri>
          </mesh>
        </geometry>
        <material>
          <script>
            <name>Gazebo/DarkGrey</name>
            <uri>file://media/materials/scripts/gazebo.material</uri>
          </script>
        </material>
      </visual>
      <self_collide>1</self_collide>
    </link>
    <joint name='joint1' type='revolute'>
      <pose relative_to='link1'>0.012 0 0.017 0 -0 0</pose>
      <parent>link1</parent>
      <child>link2</child>
      <axis>
        <xyz>0 0 1</xyz>
        <limit>
          <lower>-2.82743</lower>
          <upper>2.82743</upper>
          <effort>1</effort>
          <velocity>4.8</velocity>
        </limit>
        <dynamics>
          <damping>10</damping>
          <friction>1</friction>
          <spring_reference>0</spring_reference>
          <spring_stiffness>0</spring_stiffness>
        </dynamics>
      </axis>
    </joint>
    <link name='link2'>
      <pose relative_to='joint1'>0 0 0 0 -0 0</pose>
      <inertial>
        <pose>-0.000302 0.00054 0.000474 0 -0 0</pose>
        <mass>0.0984068</mass>
        <inertia>
          <ixx>3.45434e-05</ixx>
          <ixy>-1.60311e-08</ixy>
          <ixz>-3.83752e-07</ixz>
          <iyy>3.26893e-05</iyy>
          <iyz>2.85119e-08</iyz>
          <izz>1.88503e-05</izz>
        </inertia>
      </inertial>
      <collision name='link2_collision'>
        <pose>0 0 0.019 0 -0 0</pose>
        <geometry>
          <mesh>
            <scale>0.001 0.001 0.001</scale>
            <uri>file:///home/csi/TTR_ws/install/open_manipulator_x_description/share/open_manipulator_x_description/meshes/chain_link2.stl</uri>
          </mesh>
        </geometry>
        <surface>
          <contact>
            <ode/>
          </contact>
          <friction>
            <ode/>
          </friction>
        </surface>
      </collision>
      <visual name='link2_visual'>
        <pose>0 0 0.019 0 -0 0</pose>
        <geometry>
          <mesh>
            <scale>0.001 0.001 0.001</scale>
            <uri>file:///home/csi/TTR_ws/install/open_manipulator_x_description/share/open_manipulator_x_description/meshes/chain_link2.stl</uri>
          </mesh>
        </geometry>
        <material>
          <script>
            <name>Gazebo/Red</name>
            <uri>file://media/materials/scripts/gazebo.material</uri>
          </script>
        </material>
      </visual>
      <self_collide>1</self_collide>
    </link>
    <joint name='joint2' type='revolute'>
      <pose relative_to='link2'>0 0 0.0595 0 -0 0</pose>
      <parent>link2</parent>
      <child>link3</child>
      <axis>
        <xyz>0 1 0</xyz>
        <limit>
          <lower>-1.79071</lower>
          <upper>1.5708</upper>
          <effort>1</effort>
          <velocity>4.8</velocity>
        </limit>
        <dynamics>
          <damping>10</damping>
          <friction>1</friction>
          <spring_reference>0</spring_reference>
          <spring_stiffness>0</spring_stiffness>
        </dynamics>
      </axis>
    </joint>
    <link name='link3'>
      <pose relative_to='joint2'>0 0 0 0 -0 0</pose>
      <inertial>
        <pose>0.010308 0.000377 0.101702 0 -0 0</pose>
        <mass>0.138509</mass>
        <inertia>
          <ixx>0.000330554</ixx>
          <ixy>-9.7941e-08</ixy>
          <ixz>-3.85057e-05</ixz>
          <iyy>0.000342904</iyy>
          <iyz>-1.57175e-06</iyz>
          <izz>6.03465e-05</izz>
        </inertia>
      </inertial>
      <collision name='link3_collision'>
        <pose>0 0 0 0 -0 0</pose>
        <geometry>
          <mesh>
            <scale>0.001 0.001 0.001</scale>
            <uri>file:///home/csi/TTR_ws/install/open_manipulator_x_description/share/open_manipulator_x_description/meshes/chain_link3.stl</uri>
          </mesh>
        </geometry>
        <surface>
          <contact>
            <ode/>
          </contact>
          <friction>
            <ode/>
          </friction>
        </surface>
      </collision>
      <visual name='link3_visual'>
        <pose>0 0 0 0 -0 0</pose>
        <geometry>
          <mesh>
            <scale>0.001 0.001 0.001</scale>
            <uri>file:///home/csi/TTR_ws/install/open_manipulator_x_description/share/open_manipulator_x_description/meshes/chain_link3.stl</uri>
          </mesh>
        </geometry>
        <material>
          <script>
            <name>Gazebo/Green</name>
            <uri>file://media/materials/scripts/gazebo.material</uri>
          </script>
        </material>
      </visual>
      <self_collide>1</self_collide>
    </link>
    <joint name='joint3' type='revolute'>
      <pose relative_to='link3'>0.004 -0.026 0.108 0 -0 0</pose>
      <parent>link3</parent>
      <child>link4</child>
      <axis>
        <xyz>0 1 0</xyz>
        <limit>
          <lower>-0.942478</lower>
          <upper>1.3823</upper>
          <effort>1</effort>
          <velocity>4.8</velocity>
        </limit>
        <dynamics>
          <damping>10</damping>
          <friction>1</friction>
          <spring_reference>0</spring_reference>
          <spring_stiffness>0</spring_stiffness>
        </dynamics>
      </axis>
    </joint>
    <link name='link4'>
      <pose relative_to='joint3'>0 0 0 0 -0 0</pose>
      <inertial>
        <pose>0.044207 0 0.008914 0 -0 0</pose>
        <mass>0.143276</mass>
        <inertia>
          <ixx>8.08707e-05</ixx>
          <ixy>0</ixy>
          <ixz>-1.01579e-06</ixz>
          <iyy>7.59805e-05</iyy>
          <iyz>0</iyz>
          <izz>9.31274e-05</izz>
        </inertia>
      </inertial>
      <collision name='link4_collision'>
        <pose>0 0 0 0 -0 0</pose>
        <geometry>
          <mesh>
            <scale>0.001 0.001 0.001</scale>
            <uri>file:///home/csi/TTR_ws/install/open_manipulator_x_description/share/open_manipulator_x_description/meshes/chain_link4.stl</uri>
          </mesh>
        </geometry>
        <surface>
          <contact>
            <ode/>
          </contact>
          <friction>
            <ode/>
          </friction>
        </surface>
      </collision>
      <visual name='link4_visual'>
        <pose>0 0 0 0 -0 0</pose>
        <geometry>
          <mesh>
            <scale>0.001 0.001 0.001</scale>
            <uri>file:///home/csi/TTR_ws/install/open_manipulator_x_description/share/open_manipulator_x_description/meshes/chain_link4.stl</uri>
          </mesh>
        </geometry>
        <material>
          <script>
            <name>Gazebo/Blue</name>
            <uri>file://media/materials/scripts/gazebo.material</uri>
          </script>
        </material>
      </visual>
      <self_collide>1</self_collide>
    </link>
    <joint name='joint4' type='revolute'>
      <pose relative_to='link4'>0.091989 0.026 0.01999 0 1.5707 0</pose>
      <parent>link4</parent>
      <child>paddle</child>
      <axis>
        <xyz>1 0 0</xyz>
        <limit>
          <lower>-3.14</lower>
          <upper>3.14</upper>
          <effort>1</effort>
          <velocity>4.8</velocity>
        </limit>
        <dynamics>
          <damping>10</damping>
          <friction>1</friction>
          <spring_reference>0</spring_reference>
          <spring_stiffness>0</spring_stiffness>
        </dynamics>
      </axis>
    </joint>
    <link name='paddle'>
      <pose relative_to='joint4'>0 0 0 0 -0 0</pose>
      <inertial>
        <pose>0 0 0 0 -0 0</pose>
        <mass>0.002</mass>
        <inertia>
          <ixx>0.002</ixx>
          <ixy>0</ixy>
          <ixz>0</ixz>
          <iyy>0.002</iyy>
          <iyz>0</iyz>
          <izz>0.002</izz>
        </inertia>
      </inertial>
      <collision name='paddle_collision'>
        <pose>0 0 0 0 -0 0</pose>
        <geometry>
          <mesh>
            <scale>0.0005 0.0005 0.0005</scale>
            <uri>file:///home/csi/TTR_ws/install/open_manipulator_x_description/share/open_manipulator_x_description/meshes/paddle.stl</uri>
          </mesh>
        </geometry>
        <surface>
          <contact>
            <ode/>
          </contact>
          <friction>
            <ode/>
          </friction>
        </surface>
      </collision>
      <visual name='paddle_visual'>
        <pose>0 0 0 0 -0 0</pose>
        <geometry>
          <mesh>
            <scale>0.0005 0.0005 0.0005</scale>
            <uri>file:///home/csi/TTR_ws/install/open_manipulator_x_description/share/open_manipulator_x_description/meshes/paddle.stl</uri>
          </mesh>
        </geometry>
        <material>
          <script>
            <name>Gazebo/Yellow</name>
            <uri>file://media/materials/scripts/gazebo.material</uri>
          </script>
        </material>
      </visual>
      <self_collide>1</self_collide>
    </link>
    <static>0</static>
    <plugin name='gazebo_ros2_control' filename='libgazebo_ros2_control.so'>
      <robot_sim_type>gazebo_ros2_control/GazeboSystem</robot_sim_type>
      <parameters>/home/csi/TTR_ws/install/open_manipulator_x_description/share/open_manipulator_x_description/config/open_manipulator_x_controller.yaml</parameters>
      <robot_param_node>/open_manipulator_x0/robot_state_publisher</robot_param_node>
    </plugin>
  </model>
</sdf>
