<?xml version="1.0" ?>
<!-- =================================================================================== -->
<!-- |    This document was autogenerated by xacro from open_manipulator_x_robot.urdf.xacro | -->
<!-- |    EDITING THIS FILE BY HAND IS NOT RECOMMENDED                                 | -->
<!-- =================================================================================== -->
<robot name="open_manipulator_x">
    <link name="link0">
        <visual>
            <origin rpy="0.0 0.0 0.0" xyz="0.0 0.0 0.0"/>
            <geometry>
                <box size="0.80 0.05 0.03"/>
            </geometry>
            <material name="grey"/>
        </visual>
        <collision>
            <origin rpy="0.0 0.0 0.0" xyz="0.0 0.0 0.0"/>
            <geometry>
                <box size="0.80 0.05 0.03"/>
            </geometry>
        </collision>
        <inertial>
            <mass value="100.0"/>
            <inertia ixx="1.0" ixy="0.0" ixz="0.0" iyy="1.0" iyz="0.0" izz="1.0"/>
        </inertial>
    </link>
    <link name="link1">
        <visual>
            <origin rpy="0 0 0" xyz="0 0 0"/>
            <geometry>
                <mesh filename="file:///home/csi/TTR_ws/install/open_manipulator_x_description/share/open_manipulator_x_description/meshes/chain_link1.stl" scale="0.001 0.001 0.001"/>
            </geometry>
            <meterial name="grey"/>
        </visual>
        <collision>
            <origin rpy="0 0 0" xyz="0 0 0"/>
            <geometry>
                <mesh filename="file:///home/csi/TTR_ws/install/open_manipulator_x_description/share/open_manipulator_x_description/meshes/chain_link1.stl" scale="0.001 0.001 0.001"/>
            </geometry>
        </collision>
        <inertial>
            <origin xyz="3.0876154e-04 0.0000000e+00 -1.2176461e-04"/>
            <mass value="7.9119962e-02"/>
            <inertia ixx="1.2505234e-05" ixy="0.0" ixz="-1.7855208e-07" iyy="2.1898364e-05" iyz="0.0" izz="1.9267361e-05"/>
        </inertial>
    </link>
    <link name="link2">
        <visual>
            <origin rpy="0.0 0.0 0.0" xyz="0 0 0.019"/>
            <geometry>
                <mesh filename="file:///home/csi/TTR_ws/install/open_manipulator_x_description/share/open_manipulator_x_description/meshes/chain_link2.stl" scale="0.001 0.001 0.001"/>
            </geometry>
            <meterial name="grey"/>
        </visual>
        <collision>
            <origin rpy="0.0 0.0 0.0" xyz="0.0 0.0 0.019"/>
            <geometry>
                <mesh filename="file:///home/csi/TTR_ws/install/open_manipulator_x_description/share/open_manipulator_x_description/meshes/chain_link2.stl" scale="0.001 0.001 0.001"/>
            </geometry>
        </collision>
        <inertial>
            <origin xyz="-3.0184870e-04 5.4043684e-04 0.047433464e-02"/>
            <mass value="9.8406837e-02"/>
            <inertia ixx="3.4543422e-05" ixy="-1.6031095e-08" ixz="-3.8375155e-07" iyy="3.2689329e-05" iyz="2.8511935e-08" izz="1.8850320e-05"/>
        </inertial>
    </link>
    <link name="link3">
        <visual>
            <origin rpy="0.0 0.0 0.0" xyz="0.0 0.0 0.0"/>
            <geometry>
                <mesh filename="file:///home/csi/TTR_ws/install/open_manipulator_x_description/share/open_manipulator_x_description/meshes/chain_link3.stl" scale="0.001 0.001 0.001"/>
            </geometry>
            <material name="grey"/>
        </visual>
        <collision>
            <origin rpy="0.0 0.0 0.0" xyz="0.0 0.0 0.0"/>
            <geometry>
                <mesh filename="file:///home/csi/TTR_ws/install/open_manipulator_x_description/share/open_manipulator_x_description/meshes/chain_link3.stl" scale="0.001 0.001 0.001"/>
            </geometry>
        </collision>
        <inertial>
            <origin xyz="1.0308393e-02 3.7743363e-04 1.0170197e-01"/>
            <mass value="1.3850917e-01"/>
            <inertia ixx="3.3055381e-04" ixy="-9.7940978e-08" ixz="-3.8505711e-05" iyy="3.4290447e-04" iyz="-1.5717516e-06" izz="6.0346498e-05"/>
        </inertial>
    </link>
    <link name="link4">
        <visual>
            <origin rpy="0.0 0.0 0.0" xyz="0.0 0.0 0.0"/>
            <geometry>
                <mesh filename="file:///home/csi/TTR_ws/install/open_manipulator_x_description/share/open_manipulator_x_description/meshes/chain_link4.stl" scale="0.001 0.001 0.001"/>
            </geometry>
            <material name="grey"/>
        </visual>
        <collision>
            <origin rpy="0.0 0.0 0.0" xyz="0.0 0.0 0.0"/>
            <geometry>
                <mesh filename="file:///home/csi/TTR_ws/install/open_manipulator_x_description/share/open_manipulator_x_description/meshes/chain_link4.stl" scale="0.001 0.001 0.001"/>
            </geometry>
        </collision>
        <inertial>
            <origin xyz="4.4206755e-02 3.6839985e-07 8.9142216e-03"/>
            <mass value="1.4327573e-01"/>
            <inertia ixx="8.0870749e-05" ixy="0.0" ixz="-1.0157896e-06" iyy="7.5980465e-05" iyz="0.0" izz="9.3127351e-05"/>
        </inertial>
    </link>
    <link name="paddle">
        <visual>
            <origin rpy="0.0 0.0 0.0" xyz="0.0 0.0 0.0"/>
            <geometry>
                <mesh filename="file:///home/csi/TTR_ws/install/open_manipulator_x_description/share/open_manipulator_x_description/meshes/paddle.stl" scale="0.0005 0.0005 0.0005"/>
            </geometry>
            <material name="grey"/>
        </visual>
        <collision>
            <origin rpy="0.0 0.0 0.0" xyz="0.0 0.0 0.0"/>
            <geometry>
                <mesh filename="file:///home/csi/TTR_ws/install/open_manipulator_x_description/share/open_manipulator_x_description/meshes/paddle.stl" scale="0.0005 0.0005 0.0005"/>
            </geometry>
        </collision>
        <inertial>
            <origin xyz="0 0 0"/>
            <mass value="2.0e-03"/>
            <inertia ixx="2.0e-03" ixy="0.0" ixz="0.0" iyy="2.0e-03" iyz="0.0" izz="2.0e-03"/>
        </inertial>
    </link>
    <joint name="prismatic_joint" type="prismatic">
        <axis xyz="1 0 0"/>
        <origin rpy="0 0 -1.5707" xyz="0.0 0.0 0.0"/>
        <parent link="link0"/>
        <child link="link1"/>
        <limit effort="1000.0" lower="-35" upper="35" velocity="20"/>
        <dynamics damping="10.0" friction="1.0"/>
    </joint>
    <joint name="joint1" type="revolute">
        <origin rpy="0 0 0" xyz="0.012 0.0 0.017"/>
        <parent link="link1"/>
        <child link="link2"/>
        <axis xyz="0 0 1"/>
        <limit effort="1" lower="-2.82743338823" upper="2.82743338823" velocity="4.8"/>
        <dynamics damping="10.0" friction="1.0"/>
    </joint>
    <joint name="joint2" type="revolute">
        <origin rpy="0 0 0" xyz="0.0 0.0 0.0595"/>
        <parent link="link2"/>
        <child link="link3"/>
        <axis xyz="0 1 0"/>
        <limit effort="1" lower="-1.79070781255" upper="1.57079632679" velocity="4.8"/>
        <dynamics damping="10.0" friction="1.0"/>
    </joint>
    <joint name="joint3" type="revolute">
        <origin rpy="0 0 0" xyz="0.004 -0.026 0.108"/>
        <parent link="link3"/>
        <child link="link4"/>
        <axis xyz="0 1 0"/>
        <limit effort="1" lower="-0.94247779607" upper="1.38230076758" velocity="4.8"/>
        <dynamics damping="10.0" friction="1.0"/>
    </joint>
    <joint name="joint4" type="revolute">
        <origin rpy="0 1.5707 0" xyz="0.091989 0.026 0.01999"/>
        <parent link="link4"/>
        <child link="paddle"/>
        <axis xyz="1 0 0"/>
        <limit effort="1" lower="-3.14" upper="3.14" velocity="4.8"/>
        <dynamics damping="10.0" friction="1.0"/>
    </joint>
    <gazebo reference="link1">
        <material>Gazebo/DarkGrey</material>
        <selfCollide>True</selfCollide>
    </gazebo>
    <gazebo reference="link2">
        <material>Gazebo/Red</material>
        <selfCollide>True</selfCollide>
    </gazebo>
    <gazebo reference="link3">
        <material>Gazebo/Green</material>
        <selfCollide>True</selfCollide>
    </gazebo>
    <gazebo reference="link4">
        <material>Gazebo/Blue</material>
        <selfCollide>True</selfCollide>
    </gazebo>
    <gazebo reference="paddle">
        <material>Gazebo/Yellow</material>
        <selfCollide>True</selfCollide>
    </gazebo>
    <ros2_control name="GazeboSystem" type="system">
        <hardware>
            <plugin>gazebo_ros2_control/GazeboSystem</plugin>
        </hardware>
        <joint name="joint1">
            <command_interface name="position">
                <param name="min">-2.82743338823</param>
                <param name="max">2.82743338823</param>
            </command_interface>
            <state_interface name="position"/>
            <state_interface name="velocity"/>
            <state_interface name="effort"/>
        </joint>
        <joint name="joint2">
            <command_interface name="position">
                <param name="min">-1.79070781255</param>
                <param name="max">1.57079632679</param>
            </command_interface>
            <state_interface name="position"/>
            <state_interface name="velocity"/>
            <state_interface name="effort"/>
        </joint>
        <joint name="joint3">
            <command_interface name="position">
                <param name="min">-0.94247779607</param>
                <param name="max">1.38230076758</param>
            </command_interface>
            <state_interface name="position"/>
            <state_interface name="velocity"/>
            <state_interface name="effort"/>
        </joint>
        <joint name="joint4">
            <command_interface name="position">
                <param name="min">-3.14</param>
                <param name="max">3.14</param>
            </command_interface>
            <state_interface name="position"/>
            <state_interface name="velocity"/>
            <state_interface name="effort"/>
        </joint>
    </ros2_control>
    <gazebo>
        <plugin filename="libgazebo_ros2_control.so" name="gazebo_ros2_control">
            <!--robot_sim_type>gazebo_ros2_control/DefaultRobotHWSim</robot_sim_type-->
            <ros>
                <namespace>/open_manipulator_x1</namespace>
            </ros>
            <robotNamespace>/open_manipulator_x1</robotNamespace>
            <robot_sim_type>gazebo_ros2_control/GazeboSystem</robot_sim_type>
            <parameters>/home/csi/TTR_ws/install/open_manipulator_x_description/share/open_manipulator_x_description/config/open_manipulator_x_controller.yaml</parameters>
            <robot_param_node>/open_manipulator_x1/robot_state_publisher</robot_param_node>
        </plugin>
    </gazebo>

    <transmission name="tran1">
        <type>transmission_interface/SimpleTransmission</type>
        <joint name="joint1">
            <hardwareInterface>hardware_interface/PositionJointInterface</hardwareInterface>
        </joint>
        <actuator name="motor1">
            <hardwareInterface>hardware_interface/PositionJointInterface</hardwareInterface>
            <mechanicalReduction>1</mechanicalReduction>
        </actuator>
    </transmission>
    <transmission name="tran2">
        <type>transmission_interface/SimpleTransmission</type>
        <joint name="joint2">
            <hardwareInterface>hardware_interface/PositionJointInterface</hardwareInterface>
        </joint>
        <actuator name="motor2">
            <hardwareInterface>hardware_interface/PositionJointInterface</hardwareInterface>
            <mechanicalReduction>1</mechanicalReduction>
        </actuator>
    </transmission>
    <transmission name="tran3">
        <type>transmission_interface/SimpleTransmission</type>
        <joint name="joint3">
            <hardwareInterface>hardware_interface/PositionJointInterface</hardwareInterface>
        </joint>
        <actuator name="motor3">
            <hardwareInterface>hardware_interface/PositionJointInterface</hardwareInterface>
            <mechanicalReduction>1</mechanicalReduction>
        </actuator>
    </transmission>
    <transmission name="tran4">
        <type>transmission_interface/SimpleTransmission</type>
        <joint name="joint4">
            <hardwareInterface>hardware_interface/PositionJointInterface</hardwareInterface>
        </joint>
        <actuator name="motor4">
            <hardwareInterface>hardware_interface/PositionJointInterface</hardwareInterface>
            <mechanicalReduction>1</mechanicalReduction>
        </actuator>
    </transmission>
    <link name="world"/>
    <joint name="world_fixed" type="fixed">
        <origin rpy="0 0 0" xyz="0 0 0"/>
        <parent link="world"/>
        <child link="link0"/>
    </joint>
</robot>
